Workbook

Sheet Instruction Sheet
A8: Please change the Date & Currency settings of your systems for easy usage of this tool( First time only)
A9: Step 1 : Double click on Control Panel Step 2 :Select small icons in View By options(Right top Side ) - Step 3 :Select Region and Language icon Step 4 : In Format tab select "English(India)" option Step 5 :Click on Additional settings- 1. Date Settings: Select Date tab- Select Short date format as "dd-MM-yyyy" 2.Currency Settings: Select Currency tab- In Currency Symbol select "Rs." options - Click Ok
A19: Master Maintenance
A20: Office Name | C20: Strategic Alliance Auto Tieup Hub (Patna)
A21: Short Office Name | C21: SAATH, Patna
A22: Incharge Designation | C22: Incharge
A23: Address | C23: "Jeewan Prakash", Fraser Road
A24: City | C24: Patna | J24: Developed by:
A25: State | C25: Bihar | J25: 1. Ritesh K Sinha | L25: SAATH, Patna | N25: 8405802622
A26: Pin Code | C26: 800001 | J26: 2. Rajiv Ranjan | L26: PTRO | N26: 8405802652
J27: 3.Ranjeet Kumar SAATH, Patna 8409473204
A28: Release Version 4.3 Dt. 29/11/2022 | K28: (For Internal Use only)

Sheet Checlikst
A1: Checklist
A2: ='Data Entry'!B45 -> Aastha Honda Patna
A3: Claim Details
A4: Claim No. | B4: ='Data Entry'!B3 -> 0 | E4: Checked By:
A5: Policy No. | B5: ='Data Entry'!B4 -> 0
A6: Insured Name | B6: ='Data Entry'!B5 -> Mr.
A7: Expiry Date | B7: ='Data Entry'!D10 -> 0
A8: Reg. No. | B8: ='Data Entry'!B18 -> 0
A9: Model | B9: ='Data Entry'!B23 -> M/S Maruti
A10: Date of Accident | B10: ='Data Entry'!B38 -> 0
A12: Document Submitted
B13: DL Copy | E13: FIR Copy
B14: Policy Copy | E14: Reg. Copy
B15: Claim Form Duly Filled
B16: 64 VB | E16: NCB Certificate
B17: Invoice | E17: Estimate
B18: Photographs | E18: Satisfaction Voucher
B19: Pre-Inspection Report
A21: Surveyor Detail
A22: Spot Survey | B22: =IF('Processing Sheet'!C9<>"",'Processing Sheet'!C9,"") | C22: Survey Date | E22: =IF('Processing Sheet'!C10<>"",'Processing Sheet'!C10,"")
A23: Final Survey | B23: =IF('Processing Sheet'!F9<>"",'Processing Sheet'!F9,"") -> Dilip Kumar Sinha | C23: Survey Date | E23: =IF('Processing Sheet'!F10<>"",'Processing Sheet'!F10,"")
A24: Reinspection Survey | B24: =IF('Processing Sheet'!I9<>"",'Processing Sheet'!I9,"") | C24: Survey Date | E24: =IF('Processing Sheet'!I10<>"",'Processing Sheet'!I10,"")
A26: Assessment
A27: NIC Invoice Amount
A28: Customer Invoice Amt
A29: Money Receipt | B29: =IF('Processing Sheet'!D59<>"",'Processing Sheet'!D59,"")
A30: Assessment | B30: ='Processing Sheet'!H59 -> -1000
A31: Difference | F31: Ver 4.3
A33: ------------------------------------- Please tear from here ----------------------------------------------
A35: AKNOWLEDGEMENT
A36: ="We, hereby acknoledge the receipt of the following claim file to be submitted to National Insurance Co. Ltd, "&'Instruction Sheet'!C20 -> We, hereby acknoledge the receipt of the following claim file to be submitted to National Insurance Co. Ltd, Strategic Alliance Auto Tieup Hub (Patna)
A37: Claim No. | B37: =B4 -> 0
A38: Policy No. | B38: =B5 -> 0
A39: Insured Name | B39: =B6 -> Mr.
A40: Reg. No. | B40: =B8 -> 0
A41: Model | B41: =B9 -> M/S Maruti
A42: Date of Accident | B42: =B10 -> 0
A43: Survey Date | B43: =E23
A44: Surveyor | B44: =B23&" (SLA : "&'Data Entry'!B66&")" -> Dilip Kumar Sinha (SLA : 63315)
A46: Date :
...

Sheet Delivery Order
A3: NATIONAL INSURANCE COMPANY LIMITED
A4: ='Instruction Sheet'!C20&", "&'Instruction Sheet'!C23&", "&'Instruction Sheet'!C24&"-"&'Instruction Sheet'!C26&", "&'Instruction Sheet'!C25 -> Strategic Alliance Auto Tieup Hub (Patna), "Jeewan Prakash", Fraser Road, Patna-800001, Bihar
A6: DO / Liability Letter
F7: Date : | G7: ='Processing Sheet'!I12 -> 46137
A9: To,
A10: ='Data Entry'!B45 -> Aastha Honda Patna
A11: ='Data Entry'!H6 -> Patna
A13: ="Surveyor : "&'Data Entry'!B60 -> Surveyor : Dilip Kumar Sinha | F13: Date of Accident : | G13: ='Data Entry'!B38 -> 0
A14: ="Insured Name : " &'Data Entry'!B5 -> Insured Name : Mr.
A15: ="Vehicle Reg No : "&'Data Entry'!B18&" Chasis No. : "&'Data Entry'!B21&" Vehicle Model : "&'Data Entry'!B23 -> Vehicle Reg No : Chasis No. : Vehicle Model : M/S Maruti
A16: ="Claim No : "&'Data Entry'!B3 -> Claim No :
A17: ="Policy No. : " & 'Data Entry'!B4 -> Policy No. :
A19: With reference to the above claim details, our liability towards the above Claim as below. Request you to deliver the vehicle by collecting difference amount.
A21: ="Invocie No. : " & 'Processing Sheet'!D61 -> Invocie No. : JC25001035 | E21: Dated : | F21: ='Processing Sheet'!I61 -> 45977
A22: ="Invoice amount : Rs."&'Processing Sheet'!D60&"/-" -> Invoice amount : Rs.23047/-
A23: ="Claim Liability : Rs."&MIN('Processing Sheet'!H58,('Processing Sheet'!D60-'Processing Sheet'!D59))&"/-" -> Claim Liability : Rs.-1000/-
A25: We shall release the payment within 7 working days (if claim amount is <1.50 Lakh)/ 14 working days (if claim amount >1.5 LAKH) from the date of receipt of last relative document and money receipt.
A28: Thanks & Regards
A29: National Insurance Co Ltd
A30: SAATH, Patna
B37: Phone No. 0612-2200280/2200407 Website: www.nationalinsuranceindia.com
A42: Replacement of Parts : | D42: ="Depreciation on Metal Parts : "&'Processing Sheet'!E31&"%" -> Depreciation on Metal Parts : 0%
A43: SL NO | B43: NAME OF PARTS | C43: MATERIAL OF PARTS | D43: GST | E43: Insurance Co.'s Liability | F43: GST | G43: Insured's Liability | H43: GST
A44: 1 | B44: Cost of Paint Material (25% of Lumpsum Painting Labour Charge) | C44: PAINT (Labour) | D44: =IF('Assessment Sheet'!D79<>"",'Assessment Sheet'!D79,"") -> 0.18 | E44: =IF('Assessment Sheet'!I79<>"",'Assessment Sheet'!I79,"") -> 0 | F44: =IF('Assessment Sheet'!J79<>"",'Assessment Sheet'!J79,"") -> 0 | G44: =IF(E44<>"",('Processing Sheet'!#REF!-'Processing Sheet'!#REF!),"") -> #REF! | H44: =IF(G44<>"",G44*D44/100,"") -> #REF!
A45: 2 | B45: Cost of Paint Material (Calculated on a segregated basis Parts) | C45: PAINT | D45: =IF('Assessment Sheet'!D80<>"",'Assessment Sheet'!D80,"") -> 0.18 | E45: =IF('Assessment Sheet'!I80<>"",'Assessment Sheet'!I80,"") -> 0 | F45: =IF('Assessment Sheet'!J80<>"",'Assessment Sheet'!J80,"") -> 0 | G45: =IF('Processing Sheet'!#REF!=0,0,IF(E45<>"",('Processing Sheet'!#REF!-'Processing Sheet'!#REF!),"")) -> #REF! | H45: =IF(G45<>"",G45*D45/100,"") -> #REF!
A47: 1 | B47: =IF('Assessment Sheet'!B81<>"",'Assessment Sheet'!B81,"") | C47: =IF('Assessment Sheet'!C81<>"",'Assessment Sheet'!C81,"") -> PLASTIC | D47: =IF('Assessment Sheet'!C81<>"",'Assessment Sheet'!D81,"") -> 0.18 | E47: =IF('Assessment Sheet'!B81<>"",'Assessment Sheet'!I81,"") | F47: =IF('Assessment Sheet'!J81<>"",'Assessment Sheet'!J81,"") -> 0 | G47: =IF(E47<>"",('Processing Sheet'!#REF!-'Processing Sheet'!#REF!),"") | H47: =IF(G47<>"",G47*D47/100,"")
A48: 2 | B48: =IF('Assessment Sheet'!B82<>"",'Assessment Sheet'!B82,"") | C48: =IF('Assessment Sheet'!C82<>"",'Assessment Sheet'!C82,"") -> PLASTIC | D48: =IF('Assessment Sheet'!C82<>"",'Assessment Sheet'!D82,"") -> 0.18 | E48: =IF('Assessment Sheet'!B82<>"",'Assessment Sheet'!I82,"") | F48: =IF('Assessment Sheet'!J82<>"",'Assessment Sheet'!J82,"") -> 0 | G48: =IF(E48<>"",('Processing Sheet'!#REF!-'Processing Sheet'!#REF!),"") | H48: =IF(G48<>"",G48*D48/100,"")
A49: 3 | B49: =IF('Assessment Sheet'!B83<>"",'Assessment Sheet'!B83,"") | C49: =IF('Assessment Sheet'!C83<>"",'Assessment Sheet'!C83,"") -> PLASTIC | D49: =IF('Assessment Sheet'!C83<>"",'Assessment Sheet'!D83,"") -> 0.18 | E49: =IF('Assessment Sheet'!B83<>"",'Assessment Sheet'!I83,"") | F49: =IF('Assessment Sheet'!J83<>"",'Assessment Sheet'!J83,"") -> 0 | G49: =IF(E49<>"",('Processing Sheet'!#REF!-'Processing Sheet'!#REF!),"") | H49: =IF(G49<>"",G49*D49/100,"")
A50: 4 | B50: =IF('Assessment Sheet'!B84<>"",'Assessment Sheet'!B84,"") | C50: =IF('Assessment Sheet'!C84<>"",'Assessment Sheet'!C84,"") -> PLASTIC | D50: =IF('Assessment Sheet'!C84<>"",'Assessment Sheet'!D84,"") -> 0.18 | E50: =IF('Assessment Sheet'!B84<>"",'Assessment Sheet'!I84,"") | F50: =IF('Assessment Sheet'!J84<>"",'Assessment Sheet'!J84,"") -> 0 | G50: =IF(E50<>"",('Processing Sheet'!#REF!-'Processing Sheet'!#REF!),"") | H50: =IF(G50<>"",G50*D50/100,"")
A51: 5 | B51: =IF('Assessment Sheet'!B85<>"",'Assessment Sheet'!B85,"") | C51: =IF('Assessment Sheet'!C85<>"",'Assessment Sheet'!C85,"") -> GLASS | D51: =IF('Assessment Sheet'!C85<>"",'Assessment Sheet'!D85,"") -> 0.18 | E51: =IF('Assessment Sheet'!B85<>"",'Assessment Sheet'!I85,"") | F51: =IF('Assessment Sheet'!J85<>"",'Assessment Sheet'!J85,"") -> 0 | G51: =IF(E51<>"",('Processing Sheet'!#REF!-'Processing Sheet'!#REF!),"") | H51: =IF(G51<>"",G51*D51/100,"")
A52: 6 | B52: =IF('Assessment Sheet'!B86<>"",'Assessment Sheet'!B86,"") | C52: =IF('Assessment Sheet'!C86<>"",'Assessment Sheet'!C86,"") -> PLASTIC | D52: =IF('Assessment Sheet'!C86<>"",'Assessment Sheet'!D86,"") -> 0.18 | E52: =IF('Assessment Sheet'!B86<>"",'Assessment Sheet'!I86,"") | F52: =IF('Assessment Sheet'!J86<>"",'Assessment Sheet'!J86,"") -> 0 | G52: =IF(E52<>"",('Processing Sheet'!#REF!-'Processing Sheet'!#REF!),"") | H52: =IF(G52<>"",G52*D52/100,"")
A53: 7 | B53: =IF('Assessment Sheet'!B87<>"",'Assessment Sheet'!B87,"") | C53: =IF('Assessment Sheet'!C87<>"",'Assessment Sheet'!C87,"") | D53: =IF('Assessment Sheet'!C87<>"",'Assessment Sheet'!D87,"") | E53: =IF('Assessment Sheet'!B87<>"",'Assessment Sheet'!I87,"") | F53: =IF('Assessment Sheet'!J87<>"",'Assessment Sheet'!J87,"") -> 0 | G53: =IF(E53<>"",('Processing Sheet'!#REF!-'Processing Sheet'!#REF!),"") | H53: =IF(G53<>"",G53*D53/100,"")
A54: 8 | B54: =IF('Assessment Sheet'!B88<>"",'Assessment Sheet'!B88,"") | C54: =IF('Assessment Sheet'!C88<>"",'Assessment Sheet'!C88,"") | D54: =IF('Assessment Sheet'!C88<>"",'Assessment Sheet'!D88,"") | E54: =IF('Assessment Sheet'!B88<>"",'Assessment Sheet'!I88,"") | F54: =IF('Assessment Sheet'!J88<>"",'Assessment Sheet'!J88,"") -> 0 | G54: =IF(E54<>"",('Processing Sheet'!#REF!-'Processing Sheet'!#REF!),"") | H54: =IF(G54<>"",G54*D54/100,"")
A55: 9 | B55: =IF('Assessment Sheet'!B89<>"",'Assessment Sheet'!B89,"") | C55: =IF('Assessment Sheet'!C89<>"",'Assessment Sheet'!C89,"") | D55: =IF('Assessment Sheet'!C89<>"",'Assessment Sheet'!D89,"") | E55: =IF('Assessment Sheet'!B89<>"",'Assessment Sheet'!I89,"") | F55: =IF('Assessment Sheet'!J89<>"",'Assessment Sheet'!J89,"") -> 0 | G55: =IF(E55<>"",('Processing Sheet'!#REF!-'Processing Sheet'!#REF!),"") | H55: =IF(G55<>"",G55*D55/100,"")
A56: 10 | B56: =IF('Assessment Sheet'!B90<>"",'Assessment Sheet'!B90,"") | C56: =IF('Assessment Sheet'!C90<>"",'Assessment Sheet'!C90,"") | D56: =IF('Assessment Sheet'!C90<>"",'Assessment Sheet'!D90,"") | E56: =IF('Assessment Sheet'!B90<>"",'Assessment Sheet'!I90,"") | F56: =IF('Assessment Sheet'!J90<>"",'Assessment Sheet'!J90,"") -> 0 | G56: =IF(E56<>"",('Processing Sheet'!#REF!-'Processing Sheet'!#REF!),"") | H56: =IF(G56<>"",G56*D56/100,"")
A57: 11 | B57: =IF('Assessment Sheet'!B91<>"",'Assessment Sheet'!B91,"") | C57: =IF('Assessment Sheet'!C91<>"",'Assessment Sheet'!C91,"") | D57: =IF('Assessment Sheet'!C91<>"",'Assessment Sheet'!D91,"") | E57: =IF('Assessment Sheet'!B91<>"",'Assessment Sheet'!I91,"") | F57: =IF('Assessment Sheet'!J91<>"",'Assessment Sheet'!J91,"") -> 0 | G57: =IF(E57<>"",('Processing Sheet'!#REF!-'Processing Sheet'!#REF!),"") | H57: =IF(G57<>"",G57*D57/100,"")
A58: 12 | B58: =IF('Assessment Sheet'!B92<>"",'Assessment Sheet'!B92,"") | C58: =IF('Assessment Sheet'!C92<>"",'Assessment Sheet'!C92,"") | D58: =IF('Assessment Sheet'!C92<>"",'Assessment Sheet'!D92,"") | E58: =IF('Assessment Sheet'!B92<>"",'Assessment Sheet'!I92,"") | F58: =IF('Assessment Sheet'!J92<>"",'Assessment Sheet'!J92,"") -> 0 | G58: =IF(E58<>"",('Processing Sheet'!#REF!-'Processing Sheet'!#REF!),"") | H58: =IF(G58<>"",G58*D58/100,"")
... A71: 25 | B71: =IF('Assessment Sheet'!B105<>"",'Assessment Sheet'!B105,"") | C71: =IF('Assessment Sheet'!C105<>"",'Assessment Sheet'!C105,"") -> PLASTIC | D71: =IF('Assessment Sheet'!C105<>"",'Assessment Sheet'!D105,"") -> 0.28 | E71: =IF('Assessment Sheet'!B105<>"",'Assessment Sheet'!I105,"") | F71: =IF('Assessment Sheet'!J105<>"",'Assessment Sheet'!J105,"") -> 0 | G71: =IF(E71<>"",('Processing Sheet'!#REF!-'Processing Sheet'!#REF!),"") | H71: =IF(G71<>"",G71*D71/100,"")
A72: NET AMOUNT | E72: =SUM(E47:E71) -> 0 | F72: =SUM(F47:F71) -> 0 | G72: =SUM(G47:G71) -> 0 | H72: =SUM(H47:H71) -> 0
A76: Labour Charges:
...

Sheet Data Entry
A1: Policy Details: | F1: Reference Number | H1: DKS/ Aasth Honda/March/2024-2025
A2: TIEUP PARTNER | B2: MARUTI | F2: Survey Fee Invoice Number | H2: Report-0000/24-25
A3: CLAIM NUMBER | F3: Date of Report
A4: POLICY NUMBER
A5: NAME OF INSURED | B5: Mr. | F5: Total No of Survey Jobs Allotted | H5: 1
A6: INSURED'S PHONE NO. | F6: City Name | H6: Patna
A7: INSURED'S Email ID | F7: Class of City | H7: A
A8: TYPE OF PRIVATE VEHICLE | B8: PRIVATE CAR
A9: FINANCER NAME
A10: PERIOD OF INSURANCE | C10: To | F10: Policy Status | G10: =IF(L16>1,IF(AND(HOUR(B10)>0,L16>1),"Break Insurance","Non-Break Insurance"),"New Policy") -> New Policy
A11: IDV OF VEHICLE | F11: Developed by SAATH, Patna.
A12: NO. OF CLAIM(S) | B12: 1 | F12: Strategic Alliance Auto Tie-up Hub, “Jeevan Prakash”, Fraser Road, Patna- 800001, Bihar
A13: IMT ENDORSEMENT | B13: 7,10,28,16
A14: IMPOSED EXCESS | B14: 0
A15: VOLUNTARY EXCESS | B15: 0 | F15: Whether Engine Protect Endorsement ? | I15: Yes
A16: COMPULSORY EXCESS | B16: =IF(B5="","",E112) -> 1000 | F16: Whether Zero Depreciation Endorsement ? | I16: Yes | J16: Age of Vehicle | L16: =ROUND((B38-MIN(B19,B20))/365,2) -> 0
A17: Vehicle Details: | F17: Zero Depreciation Applicable | I17: =IF(I16="Yes",IF(B12>2,"No","Yes"),"No") -> Yes
A18: Registration Number | F18: For Nil Depreciation Policy Please select Yes From above Dropdown List. -SAATH Tieup Claims: Select Yes from above Dropdown List and its done. -Claim Hub Claims: Select Yes from above and don't forget to select 'Yes' from dropdown in Assessment Sheet as 5% of claim amount is applicable.
A19: Registration Date
A20: Vehicle Sale Date
A21: Chassis Number
A22: Engine Number
A23: Make/Model | B23: M/S Maruti
A24: Colour of Vehicle | F24: Whether Key & lock Protect Endorsement ? | I24: No
A25: Permit No. | B25: NA | F25: Whether Consumables Protect Endorsement ? | I25: No
A26: Permit Authorised by | B26: NA | F26: Whether Invoice Protect Endorsement ? | I26: No
A27: Permit Validity | B27: NA | C27: To | F27: Whether CNG Protect Endorsement in RC,POLICY,PERMIT ? | I27: No
A28: Fitness Validity | C28: To | F28: Whether case of BREAK INSURANCE,Taken break report and photographs ? | I28: No
A29: Load Challan Detail | B29: NA | F29: Whether Third party insurance valid ? | I29: Yes
A30: Cubic Capacity | D30: cc
A31: Unladen Weight (GVW) | D31: Kgs | F31: Abbreviations for Licence in India:
A32: Tax Paid Upto | B32: Road-Worthy | F32: Two wheel:
A33: Type of body | B33: Saloon | F33: MC or MCWOG: Motorcycle Without Gear
A34: Pre-Accident Condition | B34: Road-Worthy | F34: MCWG or M/CYCL.WG: Motorcycle With Gear
A35: Seating Capacity/Passenger | B35: 5 | C35: Persons
A36: 64 VB Compliance | B36: Yes | F36: Three/four wheel:
A37: Accident Details | F37: ARNT: Auto Rickshaw – Non Transport
A38: Date of accident | C38: at | F38: ART: Auto Rickshaw – Transport
A39: Place of accident | F39: LMV-NT: Light Motor Vehicle – Non Transport
A40: Date of intimation | F40: LMV-T: Light Motor Vehicle – Transport
...

Sheet Status Report
A1: ='Data Entry'!$B$60 -> Dilip Kumar Sinha | C1: ='Data Entry'!$B$61 -> V/477, Vidyapuri, Kankarbagh, Patna-800020
A2: SURVEYOR/LOSS ASSESSOR/VALUER | D2: Mobile Number | E2: ='Data Entry'!$B$63 -> 9334110636 | G2: Developed by SAATH, Patna.
A3: License No | B3: ='Data Entry'!$B$66 -> 63315 | D3: Date of Expiry | E3: ='Data Entry'!$B$67 -> 46469
A4: Email Id | B4: ='Data Entry'!$B$65 -> dilipsinha11k@gmail.com | D4: Telephone No | E4: ='Data Entry'!$B$64 -> 0
A5: STATUS REPORT
A6: PLACE OF SURVEY | C6: ='Data Entry'!$B$45 -> Aastha Honda Patna
A7: DATE OF SURVEY | C7: ='Data Entry'!$B$44 -> 0
A8: ='Data Entry'!$B$8 -> PRIVATE CAR
A9: 1 | B9: ='Data Entry'!$A$3 -> CLAIM NUMBER | C9: ='Data Entry'!$B$3 -> 0
A10: 2 | B10: ='Data Entry'!$A$4 -> POLICY NUMBER | C10: ='Data Entry'!$B$4 -> 0
A11: 3 | B11: NAME OF INSURED | C11: ='Data Entry'!$B$5 -> Mr.
A12: 4 | B12: VEHICLE NO. | C12: ='Data Entry'!$B$18 -> 0
A13: 5 | B13: NO. OF CLAIM(S) | C13: ='Data Entry'!$B$12 -> 1
A14: 6 | B14: ='Data Entry'!$A$8 -> TYPE OF PRIVATE VEHICLE | C14: ='Data Entry'!$B$8 -> PRIVATE CAR
A15: 7 | B15: PERIOD OF INSURANCE | C15: ='Data Entry'!B10 -> 0 | D15: ='Data Entry'!C10 -> To | E15: ='Data Entry'!D10 -> 0
A16: 8 | B16: PLACE OF ACCIDENT | C16: ='Data Entry'!$B$39 -> 0
A17: 9 | B17: VEHICLE SALE DATE | C17: ='Data Entry'!$B$20 -> 0
A18: 10 | B18: DATE OF LOSS | C18: ='Data Entry'!$B$38 -> 0
A19: 11 | B19: DATE OF INTIMATION | C19: ='Data Entry'!$B$40 -> 0
A20: 12 | B20: EXPECTED DATE OF DELIVERY OF ACCIDENTED VEHICLE
A21: 13 | B21: CAUSE OF LOSS | C21: ='Data Entry'!$B$46 -> As per statement of insured and also mentioned in the claim form. While the insured vehicle was en-route. At the place of accident , . Hence the damages sustained.
A22: 14 | B22: DRIVER'S NAME | C22: ='Data Entry'!$B$53 -> 0
A23: 15 | B23: ESTIMATED LOSS | C23: ='Data Entry'!$B$41 -> 0
A24: 16 | B24: ASSESSED VALUE | C24: ='Processing Sheet'!$H$58 -> -1000
A25: 17 | B25: PROFESSIONAL FEE | C25: ='Surveyor Fee'!$E$39 -> 750
A26: 18 | B26: SURVEYOR'S COMMENTS ON DISALLOWED/WEAR & TEAR/OLD DAMAGES | C26: NO
A27: 19 | B27: Remarks, if any | C27: NO
A28: 20 | B28: DOCUMENT VERIFIED? | C28: DRIVING LICENSE | E28: YES
C29: REGISTRATION CERTIFICATE/TAX TOKEN | E29: YES
C30: POLICY COPY | E30: YES
C31: PERMIT | E31: NO
C32: LOAD CHALLAN | E32: NO
C33: 64VB | E33: YES
C34: BREAK INSPECTION REPORT APPLICABLE? | E34: =IF('Data Entry'!G10="Break Insurance","Yes","No") -> No | G34: Is Break Inspection Report attached? | K34: NO
C35: AADHAAR CARD | E35: YES
C36: PAN CARD | E36: YES
A37: =IF('Data Entry'!$B$49="Yes","FIR Lodged; Driving Licence is required to be verified.","No FIR Lodged.") -> No FIR Lodged.
A39: NAME OF SURVEYOR | C39: ='Data Entry'!$B$60 -> Dilip Kumar Sinha
C41: Submitted to National Insurance Company Limited

Sheet Processing Sheet
C1: NATIONAL INSURANCE COMPANY LTD. Assessment Sheet
A5: SAATH, Patna | I5: VER 4.3 | J5: Dt. 29/11/22
A6: =IF('Data Entry'!$B$2<>"",'Data Entry'!$B$2,"") -> MARUTI
A7: REFERENCE NUMBER | C7: =IF('Data Entry'!$H$1<>"",'Data Entry'!$H$1,"") -> DKS/ Aasth Honda/March/2024-2025 | G7: DATE OF REPORT | I7: =IF('Data Entry'!$H$3<>"",'Data Entry'!$H$3,"")
A8: TYPE OF SURVEY | C8: SPOT SURVEY | F8: FINAL SURVEY | I8: RE-INSPECTION
A9: SURVEYOR | F9: =IF('Data Entry'!$B$60<>"",'Data Entry'!$B$60,"") -> Dilip Kumar Sinha
A10: DATE OF SURVEY | C10: =IF('Data Entry'!$B$50<>"",'Data Entry'!$B$50,"") | F10: =IF('Data Entry'!$B$44<>"",'Data Entry'!$B$44,"") | I10: =IF('Data Entry'!$B$51<>"",'Data Entry'!$B$51,"")
A11: PLACE OF SURVEY | F11: ='Data Entry'!$B$45 -> Aastha Honda Patna
G12: PRINTING DATE | I12: =TODAY() -> 46137
A13: POLICY DETAILS: | E13: =IF('Data Entry'!G10<>"",'Data Entry'!G10) -> New Policy | J13: =IF('Data Entry'!I17="No","Normal Policy","Zero Dep.Policy") -> Zero Dep.Policy
A14: INSURED | C14: ='Data Entry'!$B$5 -> Mr. | G14: TYPE OF POLICY | I14: ='Data Entry'!$B$8 -> PRIVATE CAR
A15: PERIOD OF INSURANCE | C15: =IF('Data Entry'!$B$10<>"",'Data Entry'!$B$10,"") | E15: TO | F15: =IF('Data Entry'!$D$10<>"",'Data Entry'!$D$10,"") | G15: ='Data Entry'!$A$3 -> CLAIM NUMBER | I15: ='Data Entry'!$B$3 -> 0
A16: POLICY NO. | C16: ='Data Entry'!$B$4 -> 0 | G16: IDV OF VEHICLE | I16: ='Data Entry'!B11 -> 0
A18: VEHICLE DETAILS: | J18: =PROPER('Data Entry'!B8) -> Private Car
A19: REGISTRATION DATE | C19: =IF('Data Entry'!$B$19<>"",'Data Entry'!$B$19,"") | E19: TO | F19: =IF('Data Entry'!$B$32<>"",'Data Entry'!$B$32,"") -> Road-Worthy | G19: REGISTRATION NO. | I19: ='Data Entry'!$B$18 -> 0
A20: CHASSIS NUMBER | C20: ='Data Entry'!$B$21 -> 0 | E20: ENGINE NO | F20: ='Data Entry'!$B$22 -> 0 | G20: MAKE/MODEL | I20: ='Data Entry'!$B$23 -> M/S Maruti
A22: DRIVERS DETAILS: | J22: =IF('Data Entry'!I15="Yes","Engine Protected Policy","") -> Engine Protected Policy
A23: NAME OF DRIVER | C23: ='Data Entry'!$B$53 -> 0 | G23: M.D.L NUMBER | I23: ='Data Entry'!$B$54 -> 0 | L23: Developed by SAATH, Patna.
A24: DATE OF ISSUE | C24: =IF('Data Entry'!$B$56<>"",'Data Entry'!$B$56,"") | E24: TO | F24: =IF('Data Entry'!$B$55<>"",'Data Entry'!$B$55,"")
A25: TYPE OF LICENSE | C25: ='Data Entry'!$B$58 -> MCWG/LMV : Light Motor Vehicle & Motor Cycle with Gear
A27: CLAIM DETAILS: | J27: ='Data Entry'!C38 -> at
A28: DATE OF ACCIDENT | C28: =IF('Data Entry'!$B$38<>"",'Data Entry'!$B$38,"") | G28: INTIMATION DATE | I28: =IF('Data Entry'!$B$40<>"",'Data Entry'!$B$40,"")
A29: PLACE OF ACCIDENT | C29: ='Data Entry'!$B$39 -> 0 | G29: ESTIMATED LOSS | I29: ='Data Entry'!$B$41 -> 0
A31: DEPRECIATION APPLICABLE FOR METAL PARTS : | E31: =IF(I31>10,50,IF(I31>5,40,IF(I31>4,35,IF(I31>3,25,IF(I31>2,15,IF(I31>1,10,IF(I31>0.5,5,0))))))) -> 0 | F31: % | G31: AGE OF VEHICLE | I31: =ROUND('Data Entry'!L16,2) -> 0 | J31: YEARS | L31: =IF(('Data Entry'!B19)<('Data Entry'!B10),YEARFRAC('Data Entry'!B38,'Data Entry'!B19),YEARFRAC('Data Entry'!B38,'Data Entry'!B10)) -> 0
A33: GST DETAILS:
D34: GST (Labour) | F34: Taxable Amount
D35: ='Data Entry'!B77 -> 0.18 | F35: ='Assessment Sheet'!H199 -> 0
D37: GST (Parts) | F37: Taxable Amount
D38: ='Data Entry'!A77 -> 0 | F38: ='Assessment Sheet'!H191 -> 0
D39: ='Data Entry'!A78 -> 0.05 | F39: ='Assessment Sheet'!H192 -> 0
D40: ='Data Entry'!A79 -> 0.12 | F40: ='Assessment Sheet'!H193 -> 0
D41: ='Data Entry'!A80 -> 0.18 | F41: ='Assessment Sheet'!H194 -> 0
D42: ='Data Entry'!A81 -> 0.28 | F42: ='Assessment Sheet'!H195 -> 0
A44: SL NO | B44: DESCRIPTION | H44: AMOUNTS
A45: 1 | B45: COST OF PAINT MATERIAL | H45: =IF('Assessment Sheet'!G71="Yes",'Assessment Sheet'!I79,'Assessment Sheet'!I80) -> 0
A46: 2 | B46: REPLACEMENT OF PARTS | H46: ='Assessment Sheet'!I180-H45 -> 0
A47: 3 | B47: LABOUR CHARGES | H47: ='Assessment Sheet'!$I$41 -> 0
A48: 4 | B48: PAINTING CHARGES | H48: ='Assessment Sheet'!$G$72 -> 0
A49: 5 | B49: TOWING CHARGES
A50: 6 | B50: GST | H50: ='Assessment Sheet'!$G$73+'Assessment Sheet'!$J$41+'Assessment Sheet'!J179 -> 0
...

Sheet Surveyor Fee
A1: SURVEY FEE BILL
A3: INVOICE NUMBER | B3: ='Data Entry'!$H2 -> Report-0000/24-25 | C3: GSTIN | D3: ='Data Entry'!B73 -> Not Appiled
A4: REFERENCE NUMBER | B4: ='Data Entry'!$H$1 -> DKS/ Aasth Honda/March/2024-2025 | D4: DATE | E4: =IF('Data Entry'!$H$3<>"",'Data Entry'!$H$3,"")
A5: NAME OF SURVEYOR | B5: ='Data Entry'!$B$60 -> Dilip Kumar Sinha | D5: License Number | E5: ='Data Entry'!B66 -> 63315
A6: ='Data Entry'!A68 -> Bank Name | B6: ='Data Entry'!$B$68 -> State Bank of India | C6: ='Data Entry'!$B$69 -> Hanuman Nagar Br. | D6: ='Data Entry'!$A$70 -> IFSC Code | E6: ='Data Entry'!$B$70 -> SBIN0009005
A7: ='Data Entry'!A71 -> Bank A/c Number | B7: ='Data Entry'!$B$71 -> 20019295926 | D7: ='Data Entry'!$A$72 -> PAN Detail | E7: ='Data Entry'!$B$72 -> APZPS2395Q
A8: DATE OF SURVEY | C8: ='Data Entry'!$B$44 -> 0 | D8: License Exipry Date | E8: ='Data Entry'!$B$67 -> 46469
A9: PLACE OF SURVEY | B9: ='Data Entry'!$B$45 -> Aastha Honda Patna | D9: ALLOTMENT OF SURVEY | E9: ='Data Entry'!$B$43 -> 0
A10: INSURED NAME | B10: ='Data Entry'!$B$5 -> Mr. | D10: POLICY NUMBER | E10: ='Data Entry'!$B$4 -> 0
A11: CLAIM NUMBER | B11: ='Data Entry'!$B$3 -> 0 | D11: ASSESSED LOSS | E11: ='Data Entry'!$B$42 -> 0
A12: VEHICLE REGN. NO. | B12: ='Data Entry'!$B$18 -> 0 | D12: ESTIMATED LOSS | E12: ='Data Entry'!$B$41 -> 0
E13: =IF(c17>200000,SUM(2000+((B15-200000)*0.5%)),IF(c17>100000,1700,IF(c17>50000,1100,IF(c17>20000,900,600))))
A14: PROFESSIONAL FEE | G14: Developed by SAATH, Patna.
A15: =IF('Data Entry'!$B$41="","Survey Fee Not Payable. Please Enter Estimated Loss in Data Entry Sheet.","Survey Fee") -> Survey Fee Not Payable. Please Enter Estimated Loss in Data Entry Sheet. | E15: =IF('Data Entry'!$B$41="",0,IF(E12>200000,MIN(SUM(2800+((E12-200000)*0.7%)),12000),IF(E12>100000,2800,IF(E12>50000,1800,IF(E12>20000,1500,850))))) -> 0
A16: Spot Survey | B16: ='Data Entry'!B50 -> 0 | C16: Not Applicable | E16: =IF(OR(C16="Not Applicable",C16=""),0,IF(C16="Below 80Kms",1000,1500)) -> 0
A17: Reinspection | B17: ='Data Entry'!B51 -> 0 | C17: Not Applicable | E17: =IF(C17="Not Applicable",0,IF(C17="Below 80Kms",1000,1500)) -> 0
A19: CONVEYANCE EXPENSE
A20: ='Data Entry'!F5 -> Total No of Survey Jobs Allotted | C20: ='Data Entry'!$H$5 -> 1
A21: =IF('Data Entry'!$H$5="","Local Conveyance Not Payable. Please Enter Number of Surveys Alloted in Data Entry Sheet.","Local Conveyance") -> Local Conveyance | E21: =IF('Data Entry'!$H$5="",0,ROUND(IF('Data Entry'!$H$7="A",750,375)/'Data Entry'!$H$5,0)) -> 750
A22: Others (Specify)
A24: DAILY ALLOWANCE
A25: Not Applicable | E25: =IF(A25="Not Applicable",0,IF(A25="Half-a-day",250,500)) -> 0
A26: Not Applicable | E26: =IF(A26="Not Applicable",0,IF(A26="Half-a-day",200,400)) -> 0
A28: PHOTO CHARGES
A29: No of Final Survey Photo | C29: 10 | D29: /Photo | E29: =IF((B29*C29)>200,200,B29*C29) -> 0
A30: No of Reinsp. Photo | C30: 10 | D30: /Photo | E30: =IF(E17=0,0,IF((B30*C30)>100,100,B30*C30)) -> 0
A31: Videography | E31: 0
A33: OTHER (OUT OF POCKET) EXPENSES
A34: Courier, Postage, etc. | E34: 0
A35: Others (Specify) | E35: 0
A37: Total Amount | E37: =IF('Processing Sheet'!H59="Pls Comment abt difference","Pls comment abt diffrences in assesment sheet",SUM(E13:E36)) -> 750
A38: GST Applicable ? | D38: No | E38: =IF(D38="Yes",E37*'Data Entry'!B77,0) -> 0
A39: TOTAL (ROUNDED OFF) | E39: =ROUND(E37+E38,0) -> 750
A43: Passed For Payment
A44: Rs_______________
D47: Surveyor's Signature
A48: Competant Authority
C49: Submitted to National Insurance Company Limited

Sheet Main Survey Report
A1: ='Data Entry'!$B$60 -> Dilip Kumar Sinha | D1: ='Data Entry'!$B$61 -> V/477, Vidyapuri, Kankarbagh, Patna-800020
A2: SURVEYOR/LOSS ASSESSOR/VALUER | D2: Mobile Number | E2: ='Data Entry'!$B$63 -> 9334110636
A3: License Number | B3: ='Data Entry'!$B$66 -> 63315 | D3: Date of Expiry | E3: ='Data Entry'!$B$67 -> 46469
A4: Email Id | B4: ='Data Entry'!$B$65 -> dilipsinha11k@gmail.com | D4: Telephone Number | E4: ='Data Entry'!$B$64 -> 0
A5: PRIVATE AND CONFIDENTIAL MOTOR (FINAL) SURVEY REPORT
A7: REFERENCE NUMBER | B7: ='Data Entry'!$H$1 -> DKS/ Aasth Honda/March/2024-2025 | D7: DATE OF REPORT | E7: =IF('Data Entry'!$H$3<>"",'Data Entry'!$H$3,"")
A8: ='Data Entry'!$B$8 -> PRIVATE CAR | C8: =IF('Data Entry'!I15="Yes","Engine Protected Policy","") -> Engine Protected Policy | E8: =IF('Data Entry'!I17="No","Normal Policy","Zero Dep.Policy") -> Zero Dep.Policy
A9: This report is issued by me as licensed surveyor without prejudice, in respect of cause, nature and extent of loss/damage and subject to the terms and conditions of the insurance policy and not binding upon the liability of Insurer or the undersigned.
G10: Developed by SAATH, Patna.
A12: POLICY STATUS | E12: ='Data Entry'!G10 -> New Policy
A13: INSURER | B13: NATIONAL INSURANCE COMPANY LTD. | D13: IDV OF VEHICLE | E13: ='Data Entry'!$B$11 -> 0
A14: INSURED | B14: ='Data Entry'!$B$5 -> Mr. | D14: INSURED's PHONE NO. | E14: ='Data Entry'!B6 -> 0
A15: EMAIL ID | B15: =IF('Data Entry'!$B$7<>"",'Data Entry'!$B$7,"") | D15: POLICY NO. | E15: ='Data Entry'!$B$4 -> 0
A16: PERIOD OF INSURANCE | B16: ='Data Entry'!$B$10 -> 0 | C16: ='Data Entry'!$D$10 -> 0 | D16: ='Data Entry'!$A$3 -> CLAIM NUMBER | E16: ='Data Entry'!$B$3 -> 0
A17: FINANCER NAME | B17: =IF('Data Entry'!$B$9<>"",'Data Entry'!$B$9,"Not Appilcable") -> Not Appilcable
A19: VEHICLE DETAILS | E19: =PROPER('Data Entry'!B8) -> Private Car
A20: REGISTRATION NO. | B20: ='Data Entry'!$B$18 -> 0 | D20: REGISTRATION DATE | E20: =IF('Data Entry'!$B$19<>"",'Data Entry'!$B$19,"")
A21: CHASSIS NUMBER | B21: ='Data Entry'!$B$21 -> 0 | D21: ENGINE NUMBER | E21: ='Data Entry'!$B$22 -> 0
A22: MAKE/MODEL | B22: ='Data Entry'!$B$23 -> M/S Maruti | D22: TYPE OF BODY | E22: ='Data Entry'!$B$33 -> Saloon
A23: CUBIC CAPACITY | B23: ='Data Entry'!$B$30 -> 0 | C23: cc | D23: COLOUR OF VEHICLE | E23: ='Data Entry'!$B$24 -> 0
A24: UNLADEN WEIGHT | B24: ='Data Entry'!$B$31 -> 0 | C24: Kgs | D24: TAX PAID UPTO | E24: =IF('Data Entry'!$B$32<>"",'Data Entry'!$B$32,"") -> Road-Worthy
A25: SEATING CAPACITY | B25: ='Data Entry'!$B$35 -> 5 | C25: Persons | D25: FIR LODGED | E25: ='Data Entry'!$B$49 -> No
A26: PERMIT NUMBER | B26: =IF('Data Entry'!$B$25<>"",'Data Entry'!$B$25,"") -> NA | D26: PERMIT AUTHORISATION DETAIL | E26: =IF('Data Entry'!$B$26<>"",'Data Entry'!$B$26,"") -> NA
A27: PERMIT VALIDITY | B27: =IF('Data Entry'!$B$27<>"",'Data Entry'!$B$27,"") -> NA | C27: =IF('Data Entry'!$D$27<>"",'Data Entry'!$D$27,"") | D27: LOAD CHALLAN DETAIL | E27: =IF('Data Entry'!$B$29<>"",'Data Entry'!$B$29,"") -> NA
A28: FITNESS VALIDITY | B28: =IF('Data Entry'!$B$28<>"",'Data Entry'!$B$28,"") | C28: =IF('Data Entry'!$D$28<>"",'Data Entry'!$D$28,"") | D28: IMT ENDORSEMENT Nos. | E28: =IF('Data Entry'!$B$13<>"",'Data Entry'!$B$13,"Pls Enter Endt Nos.") -> 7,10,28,16
A30: DRIVERS DETAILS
A31: NAME OF DRIVER | B31: ='Data Entry'!$B$53 -> 0 | D31: M.D.L NUMBER | E31: ='Data Entry'!$B$54 -> 0
A32: DATE OF ISSUE | B32: =IF('Data Entry'!$B$56<>"",'Data Entry'!$B$56,"") | D32: VALID UPTO | E32: =IF('Data Entry'!$B$55<>"",'Data Entry'!$B$55,"")
A33: ISSUING AUTHORITY | B33: ='Data Entry'!$B$57 -> D.T.O Patna | D33: TYPE OF LICENSE | E33: ='Data Entry'!$B$58 -> MCWG/LMV : Light Motor Vehicle & Motor Cycle with Gear
A35: ACCIDENT AND SURVEY DETAILS
A36: DATE OF ACCIDENT | B36: =IF('Data Entry'!$B$38<>"",'Data Entry'!$B$38,"") | D36: DATE OF APPOINTMENT | E36: =IF('Data Entry'!$B$43<>"",'Data Entry'!$B$43,"")
A37: DATE OF SURVEY | B37: =IF('Data Entry'!$B$44<>"",'Data Entry'!$B$44,"") | D37: DATE OF REINSPECTION | E37: =IF('Data Entry'!$B$51<>"",'Data Entry'!$B$51,"")
A38: PLACE OF ACCIDENT | B38: ='Data Entry'!$B$39 -> 0 | D38: NO. OF CLAIM | E38: ='Data Entry'!B12 -> 1
A39: PLACE OF SURVEY | B39: ='Data Entry'!$B$45 -> Aastha Honda Patna
A41: SUMMARY OF ASSESSMENTS | D41: ASSESSED FOR
A42: TOTAL REPLACEMENT OF PARTS INCLUDING PAINT MATERIAL | D42: ='Assessment Sheet'!I180 -> 0
A43: TOTAL LABOUR CHARGES | D43: =SUM('Processing Sheet'!$H$47,'Processing Sheet'!$H$48,'Processing Sheet'!$H$50) -> 0
A44: TOWING CHARGES | D44: ='Processing Sheet'!$H$49 -> 0
A45: LESS EXCESS | D45: =SUM('Processing Sheet'!$H$54:'Processing Sheet'!$H$56) -> 1000
A46: SALVAGE VALUE(IF ANY) | D46: ='Processing Sheet'!$H$53 -> 0
...

Sheet Assessment Sheet
A1: LABOUR AND PARTS ASSESSMENT SHEET
A3: Name of Surveyor | C3: ='Data Entry'!$B$60 -> Dilip Kumar Sinha | F3: Date of Accident | H3: =IF('Data Entry'!$B$38<>"",'Data Entry'!$B$38,"")
A4: Policy Number | C4: ='Data Entry'!$B$4 -> 0 | F4: ='Data Entry'!$A$3 -> CLAIM NUMBER | H4: ='Data Entry'!$B$3 -> 0
A5: Insured | C5: ='Data Entry'!$B$5 -> Mr. | F5: Vehicle Reg. Number | H5: ='Data Entry'!$B$18 -> 0
A6: REFERENCE NUMBER | C6: ='Data Entry'!$H$1 -> DKS/ Aasth Honda/March/2024-2025
A7: DATE OF REPORT | C7: =IF('Data Entry'!$H$3<>"",'Data Entry'!$H$3,"")
A8: Details of Damage and Labour Assessment | J8: =IF('Data Entry'!I17="No","Normal Policy","Zero Dep.Policy") -> Zero Dep.Policy
A9: Labour Charges:
A10: Sl No. | B10: Labour Charge for Damaged Parts | D10: Job Type | E10: GST (Service) | F10: Estimated Amount | G10: Billed Amount | H10: Surveyor's Assessed Amount | I10: Final Assesment Amount | J10: GST Amount
A11: 1 | D11: R&R | E11: 0.18 | I11: =MIN(IF(F11<>"",F11,0),IF(G11<>"",G11,0),IF(H11<>"",H11,0)) -> 0 | J11: =MIN(IF(F11<>"",F11,0),IF(G11<>"",G11,0),IF(H11<>"",H11,0))*E11 -> 0
A12: 2 | D12: R&R | E12: 0.18 | I12: =MIN(IF(F12<>"",F12,0),IF(G12<>"",G12,0),IF(H12<>"",H12,0)) -> 0 | J12: =MIN(IF(F12<>"",F12,0),IF(G12<>"",G12,0),IF(H12<>"",H12,0))*E12 -> 0 | L12: Developed by SAATH, Patna.
A13: 3 | D13: Repair/Dent | E13: 0.18 | I13: =MIN(IF(F13<>"",F13,0),IF(G13<>"",G13,0),IF(H13<>"",H13,0)) -> 0 | J13: =MIN(IF(F13<>"",F13,0),IF(G13<>"",G13,0),IF(H13<>"",H13,0))*E13 -> 0
A14: 4 | I14: =MIN(IF(F14<>"",F14,0),IF(G14<>"",G14,0),IF(H14<>"",H14,0)) -> 0 | J14: =MIN(IF(F14<>"",F14,0),IF(G14<>"",G14,0),IF(H14<>"",H14,0))*E14 -> 0
A15: 5 | I15: =MIN(IF(F15<>"",F15,0),IF(G15<>"",G15,0),IF(H15<>"",H15,0)) -> 0 | J15: =MIN(IF(F15<>"",F15,0),IF(G15<>"",G15,0),IF(H15<>"",H15,0))*E15 -> 0
A16: 6 | I16: =MIN(IF(F16<>"",F16,0),IF(G16<>"",G16,0),IF(H16<>"",H16,0)) -> 0 | J16: =MIN(IF(F16<>"",F16,0),IF(G16<>"",G16,0),IF(H16<>"",H16,0))*E16 -> 0
A17: 7 | I17: =MIN(IF(F17<>"",F17,0),IF(G17<>"",G17,0),IF(H17<>"",H17,0)) -> 0 | J17: =MIN(IF(F17<>"",F17,0),IF(G17<>"",G17,0),IF(H17<>"",H17,0))*E17 -> 0
A18: 8 | I18: =MIN(IF(F18<>"",F18,0),IF(G18<>"",G18,0),IF(H18<>"",H18,0)) -> 0 | J18: =MIN(IF(F18<>"",F18,0),IF(G18<>"",G18,0),IF(H18<>"",H18,0))*E18 -> 0
A19: 9 | I19: =MIN(IF(F19<>"",F19,0),IF(G19<>"",G19,0),IF(H19<>"",H19,0)) -> 0 | J19: =MIN(IF(F19<>"",F19,0),IF(G19<>"",G19,0),IF(H19<>"",H19,0))*E19 -> 0
A20: 10 | I20: =MIN(IF(F20<>"",F20,0),IF(G20<>"",G20,0),IF(H20<>"",H20,0)) -> 0 | J20: =MIN(IF(F20<>"",F20,0),IF(G20<>"",G20,0),IF(H20<>"",H20,0))*E20 -> 0
A21: 11 | I21: =MIN(IF(F21<>"",F21,0),IF(G21<>"",G21,0),IF(H21<>"",H21,0)) -> 0 | J21: =MIN(IF(F21<>"",F21,0),IF(G21<>"",G21,0),IF(H21<>"",H21,0))*E21 -> 0
A22: 12 | I22: =MIN(IF(F22<>"",F22,0),IF(G22<>"",G22,0),IF(H22<>"",H22,0)) -> 0 | J22: =MIN(IF(F22<>"",F22,0),IF(G22<>"",G22,0),IF(H22<>"",H22,0))*E22 -> 0
A23: 13 | I23: =MIN(IF(F23<>"",F23,0),IF(G23<>"",G23,0),IF(H23<>"",H23,0)) -> 0 | J23: =MIN(IF(F23<>"",F23,0),IF(G23<>"",G23,0),IF(H23<>"",H23,0))*E23 -> 0
A24: 14 | I24: =MIN(IF(F24<>"",F24,0),IF(G24<>"",G24,0),IF(H24<>"",H24,0)) -> 0 | J24: =MIN(IF(F24<>"",F24,0),IF(G24<>"",G24,0),IF(H24<>"",H24,0))*E24 -> 0
A25: 15 | I25: =MIN(IF(F25<>"",F25,0),IF(G25<>"",G25,0),IF(H25<>"",H25,0)) -> 0 | J25: =MIN(IF(F25<>"",F25,0),IF(G25<>"",G25,0),IF(H25<>"",H25,0))*E25 -> 0
... A40: 30 | I40: =MIN(IF(F40<>"",F40,0),IF(G40<>"",G40,0),IF(H40<>"",H40,0)) -> 0 | J40: =MIN(IF(F40<>"",F40,0),IF(G40<>"",G40,0),IF(H40<>"",H40,0))*E40 -> 0
A41: Total Amount | F41: =SUM(F11:F40) -> 0 | G41: =SUM(G11:G40) -> 0 | H41: =SUM(H11:H40) -> 0 | I41: =SUM(I11:I40) -> 0 | J41: =SUM(J11:J40) -> 0
A43: Labour Charges For Painting Only :
A44: Sl No. | B44: List of Damaged Parts | D44: Job Type | E44: GST (Service) | F44: Estimated Amount | G44: Billed Amount | H44: Surveyor's Assessed Amount | I44: Final Assesment Amount | J44: GST Amount
A45: 1 | D45: Painting | E45: ='Data Entry'!$B$77 -> 0.18 | I45: =MIN(IF(F45<>"",F45,0),IF(G45<>"",G45,0),IF(H45<>"",H45,0)) -> 0 | J45: =MIN(IF(F45<>"",F45,0),IF(G45<>"",G45,0),IF(H45<>"",H45,0))*E45 -> 0
A46: 2 | D46: Painting | E46: ='Data Entry'!$B$77 -> 0.18 | I46: =MIN(IF(F46<>"",F46,0),IF(G46<>"",G46,0),IF(H46<>"",H46,0)) -> 0 | J46: =MIN(IF(F46<>"",F46,0),IF(G46<>"",G46,0),IF(H46<>"",H46,0))*E46 -> 0
A47: 3 | D47: Painting | E47: ='Data Entry'!$B$77 -> 0.18 | I47: =MIN(IF(F47<>"",F47,0),IF(G47<>"",G47,0),IF(H47<>"",H47,0)) -> 0 | J47: =MIN(IF(F47<>"",F47,0),IF(G47<>"",G47,0),IF(H47<>"",H47,0))*E47 -> 0
A48: 4 | D48: Painting | I48: =MIN(IF(F48<>"",F48,0),IF(G48<>"",G48,0),IF(H48<>"",H48,0)) -> 0 | J48: =MIN(IF(F48<>"",F48,0),IF(G48<>"",G48,0),IF(H48<>"",H48,0))*E48 -> 0
A49: 5 | D49: Painting | I49: =MIN(IF(F49<>"",F49,0),IF(G49<>"",G49,0),IF(H49<>"",H49,0)) -> 0 | J49: =MIN(IF(F49<>"",F49,0),IF(G49<>"",G49,0),IF(H49<>"",H49,0))*E49 -> 0
A50: 6 | D50: Painting | I50: =MIN(IF(F50<>"",F50,0),IF(G50<>"",G50,0),IF(H50<>"",H50,0)) -> 0 | J50: =MIN(IF(F50<>"",F50,0),IF(G50<>"",G50,0),IF(H50<>"",H50,0))*E50 -> 0
A51: 7 | D51: Painting | I51: =MIN(IF(F51<>"",F51,0),IF(G51<>"",G51,0),IF(H51<>"",H51,0)) -> 0 | J51: =MIN(IF(F51<>"",F51,0),IF(G51<>"",G51,0),IF(H51<>"",H51,0))*E51 -> 0
A52: 8 | D52: Painting | I52: =MIN(IF(F52<>"",F52,0),IF(G52<>"",G52,0),IF(H52<>"",H52,0)) -> 0 | J52: =MIN(IF(F52<>"",F52,0),IF(G52<>"",G52,0),IF(H52<>"",H52,0))*E52 -> 0
A53: 9 | D53: Painting | I53: =MIN(IF(F53<>"",F53,0),IF(G53<>"",G53,0),IF(H53<>"",H53,0)) -> 0 | J53: =MIN(IF(F53<>"",F53,0),IF(G53<>"",G53,0),IF(H53<>"",H53,0))*E53 -> 0
A54: 10 | D54: Painting | I54: =MIN(IF(F54<>"",F54,0),IF(G54<>"",G54,0),IF(H54<>"",H54,0)) -> 0 | J54: =MIN(IF(F54<>"",F54,0),IF(G54<>"",G54,0),IF(H54<>"",H54,0))*E54 -> 0
A55: 11 | D55: Painting | I55: =MIN(IF(F55<>"",F55,0),IF(G55<>"",G55,0),IF(H55<>"",H55,0)) -> 0 | J55: =MIN(IF(F55<>"",F55,0),IF(G55<>"",G55,0),IF(H55<>"",H55,0))*E55 -> 0
A56: 12 | D56: Painting | I56: =MIN(IF(F56<>"",F56,0),IF(G56<>"",G56,0),IF(H56<>"",H56,0)) -> 0 | J56: =MIN(IF(F56<>"",F56,0),IF(G56<>"",G56,0),IF(H56<>"",H56,0))*E56 -> 0
...

Sheet 2022- Maruti Painting Dashboard
D1: Maruti Painting Schedule Utility
D2: ='Instruction Sheet'!C21 -> SAATH, Patna
F3: w.e.f. 22st June 2022
A4: City Category | C4: B | F4: Claim Details
A5: Dealer | C5: Alankar
A6: Model | C6: Celerio | F6: Insured Name | G6: ='Data Entry'!B5 -> Mr.
A7: Colour | C7: Metallic | F7: Policy No. | G7: ='Data Entry'!B4 -> 0
A8: Discount Mode | C8: System | F8: Claim No. | G8: ='Data Entry'!B3 -> 0
A9: No. of New Panels | C9: =COUNTIF(C12:C25,"New") -> 1 | F9: Vehicle No. | G9: ='Data Entry'!B18 -> 0
A10: No. of Old Panels | C10: =COUNTIF(C12:C25,"Old") -> 2 | F10: Surveyor's Name | G10: ='Data Entry'!B60 -> Dilip Kumar Sinha
A11: Side | B11: =B101 -> Name of Scheduled Panels | C11: =C101 -> Panel Type | D11: System Discount % | E11: Manual Discount % | F11: =H101 -> Scheduled Rate | G11: =I101 -> Discounted Rate | H11: =J101 -> Painting (Labour) | I11: =K101 -> Paint Material
A12: FR | B12: Front Bumper | C12: New | D12: =IF(OR($B12="",$C12=""),"",G102) -> 0 | E12: 0 | F12: =IF(OR(B12="",C12="",B12=0,C12=0),"",IF(OR(B12="Select",C12="Select",$C$6="Select"),"",VLOOKUP(IF(B12="Qr. Panel","Fender",B12),$B$45:$X$54,$C$88,FALSE))) -> 4029 | G12: =IF(OR($B12="",$C12=""),"",ROUND(F12*(100-IF($C$8="System",D12,E12))/100,0)) -> 4029 | H12: =IF(OR($B12="",$C12=""),"",ROUND(G12*0.75,0)) -> 3022 | I12: =IF(OR($B12="",$C12=""),"",G12-H12) -> 1007
A13: RH | B13: Fender | C13: Old | D13: =IF(OR($B13="",$C13=""),"",G103) -> 20 | E13: 30 | F13: =IF(OR(B13="",C13="",B13=0,C13=0),"",IF(OR(B13="Select",C13="Select",$C$6="Select"),"",VLOOKUP(IF(B13="Qr. Panel","Fender",B13),$B$45:$X$54,$C$88,FALSE))) -> 3258 | G13: =IF(OR($B13="",$C13=""),"",ROUND(F13*(100-IF($C$8="System",D13,E13))/100,0)) -> 2606 | H13: =IF(OR($B13="",$C13=""),"",ROUND(G13*0.75,0)) -> 1955 | I13: =IF(OR($B13="",$C13=""),"",G13-H13) -> 651
A14: RH | B14: Front Door | C14: Old | D14: =IF(OR($B14="",$C14=""),"",G104) -> 20 | E14: 30 | F14: =IF(OR(B14="",C14="",B14=0,C14=0),"",IF(OR(B14="Select",C14="Select",$C$6="Select"),"",VLOOKUP(IF(B14="Qr. Panel","Fender",B14),$B$45:$X$54,$C$88,FALSE))) -> 4408 | G14: =IF(OR($B14="",$C14=""),"",ROUND(F14*(100-IF($C$8="System",D14,E14))/100,0)) -> 3526 | H14: =IF(OR($B14="",$C14=""),"",ROUND(G14*0.75,0)) -> 2645 | I14: =IF(OR($B14="",$C14=""),"",G14-H14) -> 881
D15: =IF(OR($B15="",$C15=""),"",G105) | E15: 85 | F15: =IF(OR(B15="",C15="",B15=0,C15=0),"",IF(OR(B15="Select",C15="Select",$C$6="Select"),"",VLOOKUP(IF(B15="Qr. Panel","Fender",B15),$B$45:$X$54,$C$88,FALSE))) | G15: =IF(OR($B15="",$C15=""),"",ROUND(F15*(100-IF($C$8="System",D15,E15))/100,0)) | H15: =IF(OR($B15="",$C15=""),"",ROUND(G15*0.75,0)) | I15: =IF(OR($B15="",$C15=""),"",G15-H15)
D16: =IF(OR($B16="",$C16=""),"",G106) | F16: =IF(OR(B16="",C16="",B16=0,C16=0),"",IF(OR(B16="Select",C16="Select",$C$6="Select"),"",VLOOKUP(IF(B16="Qr. Panel","Fender",B16),$B$45:$X$54,$C$88,FALSE))) | G16: =IF(OR($B16="",$C16=""),"",ROUND(F16*(100-IF($C$8="System",D16,E16))/100,0)) | H16: =IF(OR($B16="",$C16=""),"",ROUND(G16*0.75,0)) | I16: =IF(OR($B16="",$C16=""),"",G16-H16)
D17: =IF(OR($B17="",$C17=""),"",G107) | F17: =IF(OR(B17="",C17="",B17=0,C17=0),"",IF(OR(B17="Select",C17="Select",$C$6="Select"),"",VLOOKUP(IF(B17="Qr. Panel","Fender",B17),$B$45:$X$54,$C$88,FALSE))) | G17: =IF(OR($B17="",$C17=""),"",ROUND(F17*(100-IF($C$8="System",D17,E17))/100,0)) | H17: =IF(OR($B17="",$C17=""),"",ROUND(G17*0.75,0)) | I17: =IF(OR($B17="",$C17=""),"",G17-H17)
D18: =IF(OR($B18="",$C18=""),"",G108) | F18: =IF(OR(B18="",C18="",B18=0,C18=0),"",IF(OR(B18="Select",C18="Select",$C$6="Select"),"",VLOOKUP(IF(B18="Qr. Panel","Fender",B18),$B$45:$X$54,$C$88,FALSE))) | G18: =IF(OR($B18="",$C18=""),"",ROUND(F18*(100-IF($C$8="System",D18,E18))/100,0)) | H18: =IF(OR($B18="",$C18=""),"",ROUND(G18*0.75,0)) | I18: =IF(OR($B18="",$C18=""),"",G18-H18)
D19: =IF(OR($B19="",$C19=""),"",G109) | F19: =IF(OR(B19="",C19="",B19=0,C19=0),"",IF(OR(B19="Select",C19="Select",$C$6="Select"),"",VLOOKUP(IF(B19="Qr. Panel","Fender",B19),$B$45:$X$54,$C$88,FALSE))) | G19: =IF(OR($B19="",$C19=""),"",ROUND(F19*(100-IF($C$8="System",D19,E19))/100,0)) | H19: =IF(OR($B19="",$C19=""),"",ROUND(G19*0.75,0)) | I19: =IF(OR($B19="",$C19=""),"",G19-H19)
D20: =IF(OR($B20="",$C20=""),"",G110) | F20: =IF(OR(B20="",C20="",B20=0,C20=0),"",IF(OR(B20="Select",C20="Select",$C$6="Select"),"",VLOOKUP(IF(B20="Qr. Panel","Fender",B20),$B$45:$X$54,$C$88,FALSE))) | G20: =IF(OR($B20="",$C20=""),"",ROUND(F20*(100-IF($C$8="System",D20,E20))/100,0)) | H20: =IF(OR($B20="",$C20=""),"",ROUND(G20*0.75,0)) | I20: =IF(OR($B20="",$C20=""),"",G20-H20)
D21: =IF(OR($B21="",$C21=""),"",G111) | F21: =IF(OR(B21="",C21="",B21=0,C21=0),"",IF(OR(B21="Select",C21="Select",$C$6="Select"),"",VLOOKUP(IF(B21="Qr. Panel","Fender",B21),$B$45:$X$54,$C$88,FALSE))) | G21: =IF(OR($B21="",$C21=""),"",ROUND(F21*(100-IF($C$8="System",D21,E21))/100,0)) | H21: =IF(OR($B21="",$C21=""),"",ROUND(G21*0.75,0)) | I21: =IF(OR($B21="",$C21=""),"",G21-H21)
D22: =IF(OR($B22="",$C22=""),"",G112) | F22: =IF(OR(B22="",C22="",B22=0,C22=0),"",IF(OR(B22="Select",C22="Select",$C$6="Select"),"",VLOOKUP(IF(B22="Qr. Panel","Fender",B22),$B$45:$X$54,$C$88,FALSE))) | G22: =IF(OR($B22="",$C22=""),"",ROUND(F22*(100-IF($C$8="System",D22,E22))/100,0)) | H22: =IF(OR($B22="",$C22=""),"",ROUND(G22*0.75,0)) | I22: =IF(OR($B22="",$C22=""),"",G22-H22)
D23: =IF(OR($B23="",$C23=""),"",G113) | F23: =IF(OR(B23="",C23="",B23=0,C23=0),"",IF(OR(B23="Select",C23="Select",$C$6="Select"),"",VLOOKUP(IF(B23="Qr. Panel","Fender",B23),$B$45:$X$54,$C$88,FALSE))) | G23: =IF(OR($B23="",$C23=""),"",ROUND(F23*(100-IF($C$8="System",D23,E23))/100,0)) | H23: =IF(OR($B23="",$C23=""),"",ROUND(G23*0.75,0)) | I23: =IF(OR($B23="",$C23=""),"",G23-H23)
D24: =IF(OR($B24="",$C24=""),"",G114) | F24: =IF(OR(B24="",C24="",B24=0,C24=0),"",IF(OR(B24="Select",C24="Select",$C$6="Select"),"",VLOOKUP(IF(B24="Qr. Panel","Fender",B24),$B$45:$X$54,$C$88,FALSE))) | G24: =IF(OR($B24="",$C24=""),"",ROUND(F24*(100-IF($C$8="System",D24,E24))/100,0)) | H24: =IF(OR($B24="",$C24=""),"",ROUND(G24*0.75,0)) | I24: =IF(OR($B24="",$C24=""),"",G24-H24)
D25: =IF(OR($B25="",$C25=""),"",G115) | F25: =IF(OR(B25="",C25="",B25=0,C25=0),"",IF(OR(B25="Select",C25="Select",$C$6="Select"),"",VLOOKUP(IF(B25="Qr. Panel","Fender",B25),$B$45:$X$54,$C$88,FALSE))) | G25: =IF(OR($B25="",$C25=""),"",ROUND(F25*(100-IF($C$8="System",D25,E25))/100,0)) | H25: =IF(OR($B25="",$C25=""),"",ROUND(G25*0.75,0)) | I25: =IF(OR($B25="",$C25=""),"",G25-H25)
A26: Side | B26: Other Panels | C26: Panel Name
B27: Others | G27: =IF(F27<>"",I117,"") | H27: =IF(F27<>"",J117,"") | I27: =IF(F27<>"",K117,"")
B28: Others | G28: =IF(F28<>"",I118,"") | H28: =IF(F28<>"",J118,"") | I28: =IF(F28<>"",K118,"")
B29: Others | G29: =IF(F29<>"",I119,"") | H29: =IF(F29<>"",J119,"") | I29: =IF(F29<>"",K119,"")
B30: Others | G30: =IF(F30<>"",I120,"") | H30: =IF(F30<>"",J120,"") | I30: =IF(F30<>"",K120,"")
B31: Others | G31: =IF(F31<>"",I121,"") | H31: =IF(F31<>"",J121,"") | I31: =IF(F31<>"",K121,"")
C32: Total | F32: =SUM(F12:F31) -> 11695 | G32: =SUM(G12:G31) -> 10161 | H32: =SUM(H12:H31) -> 7622 | I32: =SUM(I12:I31) -> 2539
B34: For Alankar | C34: Paint Material Rate (Per Unit) | G34: 45.65 | H34: =IF(G32=0,0,G32-I34) -> 7604.6 | I34: =IF(G32=0,0,G34*(INT(I32/G34)+1)) -> 2556.4
G40: Surveyor's Signature
B42: PAINTING SCHEDULE
B43: =VLOOKUP("Header"&I72,A125:AE278,2,FALSE)&" : "&C7 -> Panel wise Painting Charges -City Category "B" : Metallic
B44: Panels | C44: Alto-800 | D44: Alto-K10 | E44: Zen/Zen Estilo | F44: Ertiga | G44: New Wagon R | H44: A Star | I44: Ritz | J44: Swift | K44: Swift Dzire | L44: Versa/Eeco | M44: Vitara | N44: SX4 | O44: Big New Wagon R | P44: Ciaz | Q44: S-Cross | R44: Baleno (new) | S44: Celerio | T44: Vitara Brezza | U44: Ignis | V44: =+V152 -> New Ertiga | W44: Baleno (Old) | X44: Car-800 | Y44: Omni | AA44: Super Carry | AC44: Gypsy
B45: Front Bumper | C45: =VLOOKUP($I$72&$B45,$A$125:$AA$278,COLUMN(),FALSE) -> 3841 | D45: =VLOOKUP($I$72&$B45,$A$125:$AA$278,COLUMN(),FALSE) -> 4184 | E45: =VLOOKUP($I$72&$B45,$A$125:$AA$278,COLUMN(),FALSE) -> 4665 | F45: =VLOOKUP($I$72&$B45,$A$125:$AA$278,COLUMN(),FALSE) -> 4462 | G45: =VLOOKUP($I$72&$B45,$A$125:$AA$278,COLUMN(),FALSE) -> 4029 | H45: =VLOOKUP($I$72&$B45,$A$125:$AA$278,COLUMN(),FALSE) -> 4799 | I45: =VLOOKUP($I$72&$B45,$A$125:$AA$278,COLUMN(),FALSE) -> 4911 | J45: =VLOOKUP($I$72&$B45,$A$125:$AA$278,COLUMN(),FALSE) -> 4858 | ... X45: =VLOOKUP($I$72&$B45,$A$125:$AA$278,COLUMN(),FALSE) -> 0
B46: Rear Bumper | C46: =VLOOKUP($I$72&$B46,$A$125:$AA$278,COLUMN(),FALSE) -> 3841 | D46: =VLOOKUP($I$72&$B46,$A$125:$AA$278,COLUMN(),FALSE) -> 3970 | E46: =VLOOKUP($I$72&$B46,$A$125:$AA$278,COLUMN(),FALSE) -> 4109 | F46: =VLOOKUP($I$72&$B46,$A$125:$AA$278,COLUMN(),FALSE) -> 4820 | G46: =VLOOKUP($I$72&$B46,$A$125:$AA$278,COLUMN(),FALSE) -> 3906 | H46: =VLOOKUP($I$72&$B46,$A$125:$AA$278,COLUMN(),FALSE) -> 4328 | I46: =VLOOKUP($I$72&$B46,$A$125:$AA$278,COLUMN(),FALSE) -> 4473 | J46: =VLOOKUP($I$72&$B46,$A$125:$AA$278,COLUMN(),FALSE) -> 4858 | ... X46: =VLOOKUP($I$72&$B46,$A$125:$AA$278,COLUMN(),FALSE) -> 0
B47: Bonnet | C47: =VLOOKUP($I$72&$B47,$A$125:$AA$278,COLUMN(),FALSE) -> 4285 | D47: =VLOOKUP($I$72&$B47,$A$125:$AA$278,COLUMN(),FALSE) -> 4778 | E47: =VLOOKUP($I$72&$B47,$A$125:$AA$278,COLUMN(),FALSE) -> 4194 | F47: =VLOOKUP($I$72&$B47,$A$125:$AA$278,COLUMN(),FALSE) -> 4564 | G47: =VLOOKUP($I$72&$B47,$A$125:$AA$278,COLUMN(),FALSE) -> 4146 | H47: =VLOOKUP($I$72&$B47,$A$125:$AA$278,COLUMN(),FALSE) -> 3996 | I47: =VLOOKUP($I$72&$B47,$A$125:$AA$278,COLUMN(),FALSE) -> 4462 | J47: =VLOOKUP($I$72&$B47,$A$125:$AA$278,COLUMN(),FALSE) -> 4767 | ... X47: =VLOOKUP($I$72&$B47,$A$125:$AA$278,COLUMN(),FALSE) -> 3970
...

Sheet Re-inspection Report
A1: ='Data Entry'!$B$60 -> Dilip Kumar Sinha | E1: ='Data Entry'!$B$61 -> V/477, Vidyapuri, Kankarbagh, Patna-800020
A2: SURVEYOR/LOSS ASSESSOR/VALUER | E2: Mobile Number | F2: ='Data Entry'!$B$63 -> 9334110636
A3: License Number | C3: ='Data Entry'!$B$66 -> 63315 | E3: Date of Expiry | F3: ='Data Entry'!$B$67 -> 46469
A4: Email Id | C4: ='Data Entry'!$B$65 -> dilipsinha11k@gmail.com | E4: Telephone Number | F4: ='Data Entry'!$B$64 -> 0
A5: PRIVATE AND CONFIDENTIAL MOTOR (REINSPECTION) SURVEY REPORT
A7: INSURER | C7: NATIONAL INSURANCE COMPANY LTD. | E7: POLICY NO. | F7: ='Data Entry'!$B$4 -> 0
A8: INSURED | C8: ='Data Entry'!$B$5 -> Mr. | E8: ='Data Entry'!$A$3 -> CLAIM NUMBER | F8: ='Data Entry'!$B$3 -> 0
A9: PERIOD OF INSURANCE | C9: ='Data Entry'!$B$10 -> 0 | D9: ='Data Entry'!$D$10 -> 0 | E9: VEHICLE NO. | F9: ='Data Entry'!$B$18 -> 0
H10: Developed by SAATH, Patna.
A11: The aforesaid insured's vehicle number | D11: =$F$9 -> 0 | E11: was Re-inspected on | F11: ='Data Entry'!$B$51 -> 0
A12: after being intimated by the Repairer. I have inspected the vehicle minutely and found that the repairings
A13: seemly and satisfactorily. All the mechanical & electrical/electronics systems/units are working properly
A14: and the vehicle was in Roadworthy condition. During Survey I noticed that the following parts/panels are
A15: replaced as per our recommendation:
A17: Sl No | B17: Name of Parts | C17: Reason For Replacement Comment/Estimated Cost | D17: Photo of Damaged Parts | E17: Photo of Replaced Parts | F17: Photo Identification
A18: 1 | B18: =IF('Assessment Sheet'!B81<>"",'Assessment Sheet'!B81,"") | C18: =IF('Assessment Sheet'!F81<>"",'Assessment Sheet'!F81,"") | D18: Yes | E18: Yes | F18: Yes
A19: 2 | B19: =IF('Assessment Sheet'!B82<>"",'Assessment Sheet'!B82,"") | C19: =IF('Assessment Sheet'!F82<>"",'Assessment Sheet'!F82,"")
A20: 3 | B20: =IF('Assessment Sheet'!B83<>"",'Assessment Sheet'!B83,"") | C20: =IF('Assessment Sheet'!F83<>"",'Assessment Sheet'!F83,"")
A21: 4 | B21: =IF('Assessment Sheet'!B84<>"",'Assessment Sheet'!B84,"") | C21: =IF('Assessment Sheet'!F84<>"",'Assessment Sheet'!F84,"")
A22: 5 | B22: =IF('Assessment Sheet'!B85<>"",'Assessment Sheet'!B85,"") | C22: =IF('Assessment Sheet'!F85<>"",'Assessment Sheet'!F85,"")
A23: 6 | B23: =IF('Assessment Sheet'!B86<>"",'Assessment Sheet'!B86,"") | C23: =IF('Assessment Sheet'!F86<>"",'Assessment Sheet'!F86,"")
A24: 7 | B24: =IF('Assessment Sheet'!B87<>"",'Assessment Sheet'!B87,"") | C24: =IF('Assessment Sheet'!F87<>"",'Assessment Sheet'!F87,"")
A25: 8 | B25: =IF('Assessment Sheet'!B88<>"",'Assessment Sheet'!B88,"") | C25: =IF('Assessment Sheet'!F88<>"",'Assessment Sheet'!F88,"")
A26: 9 | B26: =IF('Assessment Sheet'!B89<>"",'Assessment Sheet'!B89,"") | C26: =IF('Assessment Sheet'!F89<>"",'Assessment Sheet'!F89,"")
A27: 10 | B27: =IF('Assessment Sheet'!B90<>"",'Assessment Sheet'!B90,"") | C27: =IF('Assessment Sheet'!F90<>"",'Assessment Sheet'!F90,"")
A28: 11 | B28: =IF('Assessment Sheet'!B91<>"",'Assessment Sheet'!B91,"") | C28: =IF('Assessment Sheet'!F91<>"",'Assessment Sheet'!F91,"")
A29: 12 | B29: =IF('Assessment Sheet'!B92<>"",'Assessment Sheet'!B92,"") | C29: =IF('Assessment Sheet'!F92<>"",'Assessment Sheet'!F92,"")
A30: 13 | B30: =IF('Assessment Sheet'!B93<>"",'Assessment Sheet'!B93,"") | C30: =IF('Assessment Sheet'!F93<>"",'Assessment Sheet'!F93,"")
... A115: 98 | B115: =IF('Assessment Sheet'!B178<>"",'Assessment Sheet'!B178,"") | C115: =IF('Assessment Sheet'!F178<>"",'Assessment Sheet'!F178,"")
A117: Comments(If any):
A118: NO
A120: This concludes my report which is being issued without prejudice, subject to the terms and conditions of the Insurance policy and final approval of the insurer.
B122: Thanking You,
F123: Yours faithfully,
E125: ='Data Entry'!$B$60 -> Dilip Kumar Sinha
F126: Surveyor
C131: Submitted to National Insurance Company Limited

Sheet Surveyor's Master
A1: SL | B1: Surveyor's Name | C1: Address Line | D1: Mobile Number | E1: Telephone Number | F1: Email Id | G1: License Number | H1: GSTIN | I1: Date of Expiry | J1: Bank Name | K1: Bank Addess | L1: IFSC Code | M1: Account Number | N1: PAN Detail | O1: Easy Code
A2: 1 | B2: Abhay Kumar | C2: Professors' Colony, House no.- NY / 110, Janta Road, New Yarpur, Patna - 800001 | D2: 9835240141 | F2: abhay1284.2008@rediffmail.com | G2: 43409 | H2: 10AGXPK2675G1Z8 | I2: 43344 | J2: State Bank of India | K2: Boring Rd | L2: SBIN0001435 | M2: 10749091506 | N2: AGXPK2675G
A3: 2 | B3: Amar Kant Jha | C3: 37,Mithila Colony, Road No-5, Near Baba Chowk, Patel Nagar(North) Patna-800024 | D3: 9334784485 | E3: 6122284485 | F3: amarkantjha@yahoo.com | G3: 6597 | H3: Not Appiled | I3: 43116 | J3: Indian Bank | K3: West Gandhi Maidan | L3: IDIB000P027 | M3: 537708116 | N3: ABOPJ5205B
A4: 3 | B4: Anuj Kumar | C4: B/4, Flat No.404, PRDA Apartment, South S K Puri, Patna-800001 | D4: 9835093602 | E4: 9431040529 | F4: anujkumar2259@gmail.com | G4: 36915 | H4: 10ABXPK3831D1ZW | I4: 42859 | J4: State Bank of India | K4: SPBB Patna | L4: SBIN0004070 | M4: 10498107511 | N4: ABXPK3831D
A5: 4 | B5: Arun Kumar Singh | C5: 303, Gauri Shankar Apartment (Phase-I),Kurji, Patna-800010 | D5: 9835461746 | E5: 9905246796 | F5: arunkumar.kurji@gmail.com | G5: 37267, Easi Code-95305303 | H5: 10ANZPS2969J2Z6 | I5: 45128 | J5: Uco Bank | K5: Mahalekhakar Bhawan | L5: UCBA0002050 | M5: 20500100000820 | N5: ANZPS2969J | O5: 95305303
A6: 5 | B6: Ashutosh Kumar | C6: Swastic Campus, Lane No: 3, Chandmari Road, Patna-800020 | D6: 9835089586 | F6: ashutosh_swastic@yahoo.co.in | G6: 33583 | H6: Not Appiled | I6: 42609
A7: 6 | B7: Babu Lal Prasad | C7: Bank of India Colony, Raja Bazar, Patna | D7: 9835289661 | E7: 0612-2582389 | F7: babulalprasad44@gmail.com | G7: 47276 | H7: Not Appiled | I7: 43623 | J7: State Bank of India | K7: Raja Bazar | L7: SBIN0003563 | M7: 10076879792 | N7: AGTPP9531A
A8: 7 | B8: Balbir Singh | C8: Near Loyola School, Kurji, Patna | D8: 9835097356 | E8: 9431647242 | F8: erbalbir56@gmail.com | G8: 52734 | H8: Not Appiled | I8: 44116 | J8: State Bank of India | K8: Dak Bunglow Road | L8: SBIN0007506 | M8: 10633807192 | N8: AGNPS6095G
A9: 8 | B9: Binay Kumar | C9: 607, "B", Block , Gagan Appartment, Exhibition Road, Patna-800001 | D9: 9334536429 | E9: 8084768283 | F9: binayfast@gmail.com | G9: 47434 | H9: Not Appiled | I9: 43637 | J9: Union Bank | K9: Raja Bazar | L9: UBIN545325 | M9: 453202010004415 | N9: BDOPK2556F
A10: 9 | B10: Chandra Churamani Upadhyay | C10: West Patel Nagar, Professors Colony, Patna-800023 | D10: 09431020343/7543033389 | E10: 0612-2292353 | F10: ccm_upadhyay_1961@yahoo.co.in/ccmupadhyay@gmail.com | G10: 36013 | H10: Not Appiled | I10: 42791 | J10: State Bank of India | K10: IGIMS, Patna | L10: SBIN 0007945 | M10: 10119455281 | N10: AAGPU7483D
A11: 10 | B11: Dilip Kumar Sinha | C11: V/477, Vidyapuri, Kankarbagh, Patna-800020 | D11: 9334110636 | F11: dilipsinha11k@gmail.com | G11: 63315 | H11: Not Appiled | I11: 43182 | J11: State Bank of India | K11: Hanuman Nagar Br. | L11: SBIN0009005 | M11: 20019295926 | N11: APZPS2395Q
A12: 11 | B12: Krishna Kumar Singh | C12: Patna | D12: 9431624101 | F12: kksinghsurveyor.singh@gmail.com | G12: 57716 | H12: Not Appiled | I12: 42747 | J12: HDFC Bank Ltd. | K12: Exhibition Road | L12: HDFC0000186 | M12: 01861070036004 | N12: ATAPS1143F
A13: 12 | B13: Kundan Karmvir | C13: At:-Shivpuri,Panchmandir Lane,Shivpuri Patna-800023 | D13: 9334605082 | F13: kundankarmvir@gmail.com | G13: 72838 | H13: Not Appiled | I13: 43699 | J13: State Bank of India | K13: Patliputra Colony | L13: SBIN0001513 | M13: 10636281133 | N13: AONPK5766L
A14: 13 | B14: Manoj Kumar | C14: Post Office (End), Punaichak, Patna - 800023 | D14: 9835422098 | G14: 67483 | H14: Not Appiled | I14: 43486 | J14: State Bank of India | K14: SPB Branch, Patna | L14: SBIN0004070 | M14: 10497963391 | N14: AJDPK9426C
A15: 14 | B15: Mukesh Kumar | C15: Sarmera Kothi, Road No.1, Rajendra Nagar, Patna-800016 | D15: 9835422098 | G15: 67483 | H15: Not Appiled | I15: 43486 | J15: State Bank of India | K15: Patna | L15: SBIN0004070 | M15: 10497963391 | N15: AJDPK9426C
A16: 15 | B16: Prakash Narayan | C16: New Patliputra Colony, Patna | D16: 9334660344 | F16: prakash.narayan33@gmail.com | G16: 74881 | H16: Not Appiled | I16: 43095 | J16: Punjab Bank of India | K16: Boring Rd
A17: 16 | B17: Prem Kumar Sharma | C17: H/O Dip Narayan Singh -Opp SBI , Behind ,M/S Patliputra Enterprises ,Kankarbagh , Patna-800020 | D17: 9934085231 | E17: 9523059657 | F17: sharmapremkumar49@gmail.com | G17: 70113 | H17: Not Appiled | I17: 43593 | J17: PNB | K17: Kankarbagh Branch | L17: PUNB0149900 | M17: 1.4990001e+15 | N17: AQFPS1525B
A18: 17 | B18: Raj Kumar | C18: 311, Ratnagiri Apartment, Rajabazar, Patna-800014 | D18: 9430921513 | F18: raj081963@gmail.com | G18: 27485 | H18: 10AFDPK5100P1ZT | I18: 43918 | J18: State Bank of India | K18: New Dak Bunglow Rd | L18: SBIN0003476 | M18: 10151360658 | N18: AFDPK5100P
A19: 18 | B19: Rajesh Kumar Jha | C19: 409, Sheela Residecy, Vishnudev Marg, East Boring Canal Road, Patna-800001 | D19: 9709608580 | F19: rajeshjha933@gmail.com | G19: 58085 | H19: Not Appiled | I19: 42777 | J19: State Bank of India | K19: Patliputra Colony | L19: SBIN0001513 | M19: 10636237274 | N19: ADGPJ8664C
A20: 19 | B20: Rajiv Kumar | C20: Manishakuntalam Kunj, L.B.Shastri Path, Anishabad, Patna-800002 | D20: 9431009640 | F20: manishakuntalam@yahoo.co.in | G20: 43258 | H20: Not Appiled | I20: 43338 | J20: Canara Bank | K20: Anishabad | L20: CNRB0002819 | M20: 2819101002092 | N20: AEKPK1124P
A21: 20 | B21: Ravi Ranjan Prasad | C21: PAtna | D21: 9835409936 | E21: 9471027900 | F21: rrp9936@gmail.com | G21: 37165 | H21: Not Appiled | I21: 42907 | J21: Canara Bank | K21: Exhibiton Rd. | L21: CNRB0002004 | M21: 2004101007959 | N21: AKJPP7098H
A22: 21 | B22: Sanjay K Singh (II) | C22: R-11, Jagat Vihar Colony, Ashiana Nagar, Patna-800025 | D22: 9835439174 | E22: 9546109332 | F22: sanjaysingh.surveyor@gmail.com | G22: 72510 | H22: Not Appiled | I22: 43303 | J22: State Bank of India | K22: Ashiana Nagar | L22: SBIN0009004 | M22: 010238640005 | N22: AHRPS6966R
A23: 22 | B23: Sanjay Kumar Singh | C23: C/O Vijayeshwar Pd. Road No. 1, Kankarbagh, Patna 800020 | D23: 9334847220 | E23: NA | F23: singh.sanjay67@gmail.com | G23: 51068 | H23: Not Appiled | I23: 43946 | J23: HDFC Bank Ltd | K23: Kankarbagh Branch | L23: HDFC0000477 | M23: 04772000006399 | N23: ANNPS5129G
A24: 23 | B24: Satish Kumar | C24: Ramjaipal Nagar, Gola Road, Danapur, Patna - 801503 | D24: 9835015327 | E24: 9304768851 | F24: satishkrcomp@rediffmail.com | G24: 26403 | H24: Not Appiled | I24: 43813 | J24: Union )Bank Of India | K24: Patna - Raja Bazar | L24: UBIN0545325 | M24: 453202010005804 | N24: AGOPK2068E
A25: 24 | B25: Shailesh Kumar | C25: V' Niwas, Lane-1, Salimpur Ahra, Kadam kuan, Patna-800003 | D25: 9835024275 | E25: 9939088499 | F25: shailesh64@in.com | G25: 25736 | H25: Not Appiled | I25: 43760 | J25: State Bank of India | K25: Kankarbagh Branch | L25: SBIN0004445 | M25: 30297480856 | N25: AGLPK0913D
A26: 25 | B26: Shankar Prasad Singh | C26: Ground Floor, Satyawati Complex, Kankarbagh Main Road, Patna-800020 | D26: 9431017033 | F26: spsinghsurveyor@yahoo.com | G26: 31805 | H26: Not Appiled | I26: 43555 | J26: IDBI Bank | L26: IBKL0000065 | M26: 065104000102599 | N26: AJKPS5682F
A27: 26 | B27: Someshwar Kumar | C27: H/O Manager Roy, Prof Colony, Punai Chak, Patna-800023 | D27: 9431093209 | E27: 9835015428 | F27: someshwar_08@rediffmail.com | G27: 37151 | H27: Not Appiled | I27: 42914 | J27: Punjab Bank of India | K27: Punaichak, Patna | L27: PUNB0296800 | M27: 2968000100026750 | N27: AGJPK0198A
A28: 27 | B28: Sunil Kumar | C28: 205, Deo Sidhi Plaza, Near Colony More, Main Road Kankarbagh, Patna-800020 | D28: 9835262161 | E28: 9801640402 | F28: sk.nandn@gmail.com | G28: 63836 | H28: Not Appiled | I28: 43220 | J28: IDBI Bank | K28: Kankarbagh Branch | L28: IBKL0001020 | M28: 65104000045827 | N28: AHJPK0190K
A29: 28 | B29: Upendra Narayan Singh | C29: B- 65, Biscomaun Colony, Patna- 800 007 | D29: 9431860149 | E29: 2361422 | F29: unsingh.patna@gmail.com | G29: 27819 | H29: Not Appiled | I29: 43453 | J29: OBC | K29: Exhibition Road, Patna | L29: ORBC0100231 | M29: 02312010010260 | N29: AVNPS8480N
A30: 28 | B30: Others | C30: Please fill your data in the Surveyor Master Sheet | H30: Not Appiled
